Traceback (most recent call last):
  File "/home/kostya/Documents/project8_hw5/.venv/lib/python3.10/site-packages/django/db/models/options.py", line 667, in get_field
    return self._forward_fields_map[field_name]
KeyError: 'search_vector'

During handling of the above exception, another exception occurred:

Traceback (most recent call last):
  File "/home/kostya/Documents/project8_hw5/manage.py", line 22, in <module>
    main()
  File "/home/kostya/Documents/project8_hw5/manage.py", line 18, in main
    execute_from_command_line(sys.argv)
  File "/home/kostya/Documents/project8_hw5/.venv/lib/python3.10/site-packages/django/core/management/__init__.py", line 442, in execute_from_command_line
    utility.execute()
  File "/home/kostya/Documents/project8_hw5/.venv/lib/python3.10/site-packages/django/core/management/__init__.py", line 416, in execute
    django.setup()
  File "/home/kostya/Documents/project8_hw5/.venv/lib/python3.10/site-packages/django/__init__.py", line 24, in setup
    apps.populate(settings.INSTALLED_APPS)
  File "/home/kostya/Documents/project8_hw5/.venv/lib/python3.10/site-packages/django/apps/registry.py", line 116, in populate
    app_config.import_models()
  File "/home/kostya/Documents/project8_hw5/.venv/lib/python3.10/site-packages/django/apps/config.py", line 269, in import_models
    self.models_module = import_module(models_module_name)
  File "/usr/lib/python3.10/importlib/__init__.py", line 126, in import_module
    return _bootstrap._gcd_import(name[level:], package, level)
  File "<frozen importlib._bootstrap>", line 1050, in _gcd_import
  File "<frozen importlib._bootstrap>", line 1027, in _find_and_load
  File "<frozen importlib._bootstrap>", line 1006, in _find_and_load_unlocked
  File "<frozen importlib._bootstrap>", line 688, in _load_unlocked
  File "<frozen importlib._bootstrap_external>", line 883, in exec_module
  File "<frozen importlib._bootstrap>", line 241, in _call_with_frames_removed
  File "/home/kostya/Documents/project8_hw5/app/models.py", line 46, in <module>
    class Question(models.Model):
  File "/home/kostya/Documents/project8_hw5/.venv/lib/python3.10/site-packages/django/db/models/base.py", line 365, in __new__
    new_class._prepare()
  File "/home/kostya/Documents/project8_hw5/.venv/lib/python3.10/site-packages/django/db/models/base.py", line 426, in _prepare
    index.set_name_with_model(cls)
  File "/home/kostya/Documents/project8_hw5/.venv/lib/python3.10/site-packages/django/db/models/indexes.py", line 167, in set_name_with_model
    column_names = [
  File "/home/kostya/Documents/project8_hw5/.venv/lib/python3.10/site-packages/django/db/models/indexes.py", line 168, in <listcomp>
    model._meta.get_field(field_name).column
  File "/home/kostya/Documents/project8_hw5/.venv/lib/python3.10/site-packages/django/db/models/options.py", line 672, in get_field
    raise FieldDoesNotExist(
django.core.exceptions.FieldDoesNotExist: Question has no field named 'search_vector'. The app cache isn't ready yet, so if this is an auto-created related field, it won't be available yet.
Traceback (most recent call last):
  File "/home/kostya/Documents/project8_hw5/.venv/lib/python3.10/site-packages/django/db/models/options.py", line 667, in get_field
    return self._forward_fields_map[field_name]
KeyError: 'search_vector'

During handling of the above exception, another exception occurred:

Traceback (most recent call last):
  File "/home/kostya/Documents/project8_hw5/manage.py", line 22, in <module>
    main()
  File "/home/kostya/Documents/project8_hw5/manage.py", line 18, in main
    execute_from_command_line(sys.argv)
  File "/home/kostya/Documents/project8_hw5/.venv/lib/python3.10/site-packages/django/core/management/__init__.py", line 442, in execute_from_command_line
    utility.execute()
  File "/home/kostya/Documents/project8_hw5/.venv/lib/python3.10/site-packages/django/core/management/__init__.py", line 416, in execute
    django.setup()
  File "/home/kostya/Documents/project8_hw5/.venv/lib/python3.10/site-packages/django/__init__.py", line 24, in setup
    apps.populate(settings.INSTALLED_APPS)
  File "/home/kostya/Documents/project8_hw5/.venv/lib/python3.10/site-packages/django/apps/registry.py", line 116, in populate
    app_config.import_models()
  File "/home/kostya/Documents/project8_hw5/.venv/lib/python3.10/site-packages/django/apps/config.py", line 269, in import_models
    self.models_module = import_module(models_module_name)
  File "/usr/lib/python3.10/importlib/__init__.py", line 126, in import_module
    return _bootstrap._gcd_import(name[level:], package, level)
  File "<frozen importlib._bootstrap>", line 1050, in _gcd_import
  File "<frozen importlib._bootstrap>", line 1027, in _find_and_load
  File "<frozen importlib._bootstrap>", line 1006, in _find_and_load_unlocked
  File "<frozen importlib._bootstrap>", line 688, in _load_unlocked
  File "<frozen importlib._bootstrap_external>", line 883, in exec_module
  File "<frozen importlib._bootstrap>", line 241, in _call_with_frames_removed
  File "/home/kostya/Documents/project8_hw5/app/models.py", line 46, in <module>
    class Question(models.Model):
  File "/home/kostya/Documents/project8_hw5/.venv/lib/python3.10/site-packages/django/db/models/base.py", line 365, in __new__
    new_class._prepare()
  File "/home/kostya/Documents/project8_hw5/.venv/lib/python3.10/site-packages/django/db/models/base.py", line 426, in _prepare
    index.set_name_with_model(cls)
  File "/home/kostya/Documents/project8_hw5/.venv/lib/python3.10/site-packages/django/db/models/indexes.py", line 167, in set_name_with_model
    column_names = [
  File "/home/kostya/Documents/project8_hw5/.venv/lib/python3.10/site-packages/django/db/models/indexes.py", line 168, in <listcomp>
    model._meta.get_field(field_name).column
  File "/home/kostya/Documents/project8_hw5/.venv/lib/python3.10/site-packages/django/db/models/options.py", line 672, in get_field
    raise FieldDoesNotExist(
django.core.exceptions.FieldDoesNotExist: Question has no field named 'search_vector'. The app cache isn't ready yet, so if this is an auto-created related field, it won't be available yet.
Traceback (most recent call last):
  File "/home/kostya/Documents/project8_hw5/.venv/lib/python3.10/site-packages/django/db/models/options.py", line 667, in get_field
    return self._forward_fields_map[field_name]
KeyError: 'search_vector'

During handling of the above exception, another exception occurred:

Traceback (most recent call last):
  File "/home/kostya/Documents/project8_hw5/manage.py", line 22, in <module>
    main()
  File "/home/kostya/Documents/project8_hw5/manage.py", line 18, in main
    execute_from_command_line(sys.argv)
  File "/home/kostya/Documents/project8_hw5/.venv/lib/python3.10/site-packages/django/core/management/__init__.py", line 442, in execute_from_command_line
    utility.execute()
  File "/home/kostya/Documents/project8_hw5/.venv/lib/python3.10/site-packages/django/core/management/__init__.py", line 416, in execute
    django.setup()
  File "/home/kostya/Documents/project8_hw5/.venv/lib/python3.10/site-packages/django/__init__.py", line 24, in setup
    apps.populate(settings.INSTALLED_APPS)
  File "/home/kostya/Documents/project8_hw5/.venv/lib/python3.10/site-packages/django/apps/registry.py", line 116, in populate
    app_config.import_models()
  File "/home/kostya/Documents/project8_hw5/.venv/lib/python3.10/site-packages/django/apps/config.py", line 269, in import_models
    self.models_module = import_module(models_module_name)
  File "/usr/lib/python3.10/importlib/__init__.py", line 126, in import_module
    return _bootstrap._gcd_import(name[level:], package, level)
  File "<frozen importlib._bootstrap>", line 1050, in _gcd_import
  File "<frozen importlib._bootstrap>", line 1027, in _find_and_load
  File "<frozen importlib._bootstrap>", line 1006, in _find_and_load_unlocked
  File "<frozen importlib._bootstrap>", line 688, in _load_unlocked
  File "<frozen importlib._bootstrap_external>", line 883, in exec_module
  File "<frozen importlib._bootstrap>", line 241, in _call_with_frames_removed
  File "/home/kostya/Documents/project8_hw5/app/models.py", line 46, in <module>
    class Question(models.Model):
  File "/home/kostya/Documents/project8_hw5/.venv/lib/python3.10/site-packages/django/db/models/base.py", line 365, in __new__
    new_class._prepare()
  File "/home/kostya/Documents/project8_hw5/.venv/lib/python3.10/site-packages/django/db/models/base.py", line 426, in _prepare
    index.set_name_with_model(cls)
  File "/home/kostya/Documents/project8_hw5/.venv/lib/python3.10/site-packages/django/db/models/indexes.py", line 167, in set_name_with_model
    column_names = [
  File "/home/kostya/Documents/project8_hw5/.venv/lib/python3.10/site-packages/django/db/models/indexes.py", line 168, in <listcomp>
    model._meta.get_field(field_name).column
  File "/home/kostya/Documents/project8_hw5/.venv/lib/python3.10/site-packages/django/db/models/options.py", line 672, in get_field
    raise FieldDoesNotExist(
django.core.exceptions.FieldDoesNotExist: Question has no field named 'search_vector'. The app cache isn't ready yet, so if this is an auto-created related field, it won't be available yet.
Traceback (most recent call last):
  File "/home/kostya/Documents/project8_hw5/.venv/lib/python3.10/site-packages/django/db/models/options.py", line 667, in get_field
    return self._forward_fields_map[field_name]
KeyError: 'search_vector'

During handling of the above exception, another exception occurred:

Traceback (most recent call last):
  File "/home/kostya/Documents/project8_hw5/manage.py", line 22, in <module>
    main()
  File "/home/kostya/Documents/project8_hw5/manage.py", line 18, in main
    execute_from_command_line(sys.argv)
  File "/home/kostya/Documents/project8_hw5/.venv/lib/python3.10/site-packages/django/core/management/__init__.py", line 442, in execute_from_command_line
    utility.execute()
  File "/home/kostya/Documents/project8_hw5/.venv/lib/python3.10/site-packages/django/core/management/__init__.py", line 416, in execute
    django.setup()
  File "/home/kostya/Documents/project8_hw5/.venv/lib/python3.10/site-packages/django/__init__.py", line 24, in setup
    apps.populate(settings.INSTALLED_APPS)
  File "/home/kostya/Documents/project8_hw5/.venv/lib/python3.10/site-packages/django/apps/registry.py", line 116, in populate
    app_config.import_models()
  File "/home/kostya/Documents/project8_hw5/.venv/lib/python3.10/site-packages/django/apps/config.py", line 269, in import_models
    self.models_module = import_module(models_module_name)
  File "/usr/lib/python3.10/importlib/__init__.py", line 126, in import_module
    return _bootstrap._gcd_import(name[level:], package, level)
  File "<frozen importlib._bootstrap>", line 1050, in _gcd_import
  File "<frozen importlib._bootstrap>", line 1027, in _find_and_load
  File "<frozen importlib._bootstrap>", line 1006, in _find_and_load_unlocked
  File "<frozen importlib._bootstrap>", line 688, in _load_unlocked
  File "<frozen importlib._bootstrap_external>", line 883, in exec_module
  File "<frozen importlib._bootstrap>", line 241, in _call_with_frames_removed
  File "/home/kostya/Documents/project8_hw5/app/models.py", line 46, in <module>
    class Question(models.Model):
  File "/home/kostya/Documents/project8_hw5/.venv/lib/python3.10/site-packages/django/db/models/base.py", line 365, in __new__
    new_class._prepare()
  File "/home/kostya/Documents/project8_hw5/.venv/lib/python3.10/site-packages/django/db/models/base.py", line 426, in _prepare
    index.set_name_with_model(cls)
  File "/home/kostya/Documents/project8_hw5/.venv/lib/python3.10/site-packages/django/db/models/indexes.py", line 167, in set_name_with_model
    column_names = [
  File "/home/kostya/Documents/project8_hw5/.venv/lib/python3.10/site-packages/django/db/models/indexes.py", line 168, in <listcomp>
    model._meta.get_field(field_name).column
  File "/home/kostya/Documents/project8_hw5/.venv/lib/python3.10/site-packages/django/db/models/options.py", line 672, in get_field
    raise FieldDoesNotExist(
django.core.exceptions.FieldDoesNotExist: Question has no field named 'search_vector'. The app cache isn't ready yet, so if this is an auto-created related field, it won't be available yet.
Traceback (most recent call last):
  File "/home/kostya/Documents/project8_hw5/.venv/lib/python3.10/site-packages/django/db/models/options.py", line 667, in get_field
    return self._forward_fields_map[field_name]
KeyError: 'search_vector'

During handling of the above exception, another exception occurred:

Traceback (most recent call last):
  File "/home/kostya/Documents/project8_hw5/manage.py", line 22, in <module>
    main()
  File "/home/kostya/Documents/project8_hw5/manage.py", line 18, in main
    execute_from_command_line(sys.argv)
  File "/home/kostya/Documents/project8_hw5/.venv/lib/python3.10/site-packages/django/core/management/__init__.py", line 442, in execute_from_command_line
    utility.execute()
  File "/home/kostya/Documents/project8_hw5/.venv/lib/python3.10/site-packages/django/core/management/__init__.py", line 416, in execute
    django.setup()
  File "/home/kostya/Documents/project8_hw5/.venv/lib/python3.10/site-packages/django/__init__.py", line 24, in setup
    apps.populate(settings.INSTALLED_APPS)
  File "/home/kostya/Documents/project8_hw5/.venv/lib/python3.10/site-packages/django/apps/registry.py", line 116, in populate
    app_config.import_models()
  File "/home/kostya/Documents/project8_hw5/.venv/lib/python3.10/site-packages/django/apps/config.py", line 269, in import_models
    self.models_module = import_module(models_module_name)
  File "/usr/lib/python3.10/importlib/__init__.py", line 126, in import_module
    return _bootstrap._gcd_import(name[level:], package, level)
  File "<frozen importlib._bootstrap>", line 1050, in _gcd_import
  File "<frozen importlib._bootstrap>", line 1027, in _find_and_load
  File "<frozen importlib._bootstrap>", line 1006, in _find_and_load_unlocked
  File "<frozen importlib._bootstrap>", line 688, in _load_unlocked
  File "<frozen importlib._bootstrap_external>", line 883, in exec_module
  File "<frozen importlib._bootstrap>", line 241, in _call_with_frames_removed
  File "/home/kostya/Documents/project8_hw5/app/models.py", line 46, in <module>
    class Question(models.Model):
  File "/home/kostya/Documents/project8_hw5/.venv/lib/python3.10/site-packages/django/db/models/base.py", line 365, in __new__
    new_class._prepare()
  File "/home/kostya/Documents/project8_hw5/.venv/lib/python3.10/site-packages/django/db/models/base.py", line 426, in _prepare
    index.set_name_with_model(cls)
  File "/home/kostya/Documents/project8_hw5/.venv/lib/python3.10/site-packages/django/db/models/indexes.py", line 167, in set_name_with_model
    column_names = [
  File "/home/kostya/Documents/project8_hw5/.venv/lib/python3.10/site-packages/django/db/models/indexes.py", line 168, in <listcomp>
    model._meta.get_field(field_name).column
  File "/home/kostya/Documents/project8_hw5/.venv/lib/python3.10/site-packages/django/db/models/options.py", line 672, in get_field
    raise FieldDoesNotExist(
django.core.exceptions.FieldDoesNotExist: Question has no field named 'search_vector'. The app cache isn't ready yet, so if this is an auto-created related field, it won't be available yet.
Traceback (most recent call last):
  File "/home/kostya/Documents/project8_hw5/manage.py", line 22, in <module>
    main()
  File "/home/kostya/Documents/project8_hw5/manage.py", line 18, in main
    execute_from_command_line(sys.argv)
  File "/home/kostya/Documents/project8_hw5/.venv/lib/python3.10/site-packages/django/core/management/__init__.py", line 442, in execute_from_command_line
    utility.execute()
  File "/home/kostya/Documents/project8_hw5/.venv/lib/python3.10/site-packages/django/core/management/__init__.py", line 436, in execute
    self.fetch_command(subcommand).run_from_argv(self.argv)
  File "/home/kostya/Documents/project8_hw5/.venv/lib/python3.10/site-packages/django/core/management/base.py", line 413, in run_from_argv
    self.execute(*args, **cmd_options)
  File "/home/kostya/Documents/project8_hw5/.venv/lib/python3.10/site-packages/django/core/management/base.py", line 454, in execute
    self.check()
  File "/home/kostya/Documents/project8_hw5/.venv/lib/python3.10/site-packages/django/core/management/base.py", line 486, in check
    all_issues = checks.run_checks(
  File "/home/kostya/Documents/project8_hw5/.venv/lib/python3.10/site-packages/django/core/checks/registry.py", line 88, in run_checks
    new_errors = check(app_configs=app_configs, databases=databases)
  File "/home/kostya/Documents/project8_hw5/.venv/lib/python3.10/site-packages/django/core/checks/urls.py", line 14, in check_url_config
    return check_resolver(resolver)
  File "/home/kostya/Documents/project8_hw5/.venv/lib/python3.10/site-packages/django/core/checks/urls.py", line 24, in check_resolver
    return check_method()
  File "/home/kostya/Documents/project8_hw5/.venv/lib/python3.10/site-packages/django/urls/resolvers.py", line 519, in check
    for pattern in self.url_patterns:
  File "/home/kostya/Documents/project8_hw5/.venv/lib/python3.10/site-packages/django/utils/functional.py", line 47, in __get__
    res = instance.__dict__[self.name] = self.func(instance)
  File "/home/kostya/Documents/project8_hw5/.venv/lib/python3.10/site-packages/django/urls/resolvers.py", line 738, in url_patterns
    patterns = getattr(self.urlconf_module, "urlpatterns", self.urlconf_module)
  File "/home/kostya/Documents/project8_hw5/.venv/lib/python3.10/site-packages/django/utils/functional.py", line 47, in __get__
    res = instance.__dict__[self.name] = self.func(instance)
  File "/home/kostya/Documents/project8_hw5/.venv/lib/python3.10/site-packages/django/urls/resolvers.py", line 731, in urlconf_module
    return import_module(self.urlconf_name)
  File "/usr/lib/python3.10/importlib/__init__.py", line 126, in import_module
    return _bootstrap._gcd_import(name[level:], package, level)
  File "<frozen importlib._bootstrap>", line 1050, in _gcd_import
  File "<frozen importlib._bootstrap>", line 1027, in _find_and_load
  File "<frozen importlib._bootstrap>", line 1006, in _find_and_load_unlocked
  File "<frozen importlib._bootstrap>", line 688, in _load_unlocked
  File "<frozen importlib._bootstrap_external>", line 883, in exec_module
  File "<frozen importlib._bootstrap>", line 241, in _call_with_frames_removed
  File "/home/kostya/Documents/project8_hw5/askme_pupkin/urls.py", line 22, in <module>
    from app import views
  File "/home/kostya/Documents/project8_hw5/app/views.py", line 424, in <module>
    import requests
ModuleNotFoundError: No module named 'requests'
Traceback (most recent call last):
  File "/home/kostya/Documents/project8_hw5/manage.py", line 22, in <module>
    main()
  File "/home/kostya/Documents/project8_hw5/manage.py", line 18, in main
    execute_from_command_line(sys.argv)
  File "/home/kostya/Documents/project8_hw5/.venv/lib/python3.10/site-packages/django/core/management/__init__.py", line 442, in execute_from_command_line
    utility.execute()
  File "/home/kostya/Documents/project8_hw5/.venv/lib/python3.10/site-packages/django/core/management/__init__.py", line 436, in execute
    self.fetch_command(subcommand).run_from_argv(self.argv)
  File "/home/kostya/Documents/project8_hw5/.venv/lib/python3.10/site-packages/django/core/management/base.py", line 413, in run_from_argv
    self.execute(*args, **cmd_options)
  File "/home/kostya/Documents/project8_hw5/.venv/lib/python3.10/site-packages/django/core/management/base.py", line 454, in execute
    self.check()
  File "/home/kostya/Documents/project8_hw5/.venv/lib/python3.10/site-packages/django/core/management/base.py", line 486, in check
    all_issues = checks.run_checks(
  File "/home/kostya/Documents/project8_hw5/.venv/lib/python3.10/site-packages/django/core/checks/registry.py", line 88, in run_checks
    new_errors = check(app_configs=app_configs, databases=databases)
  File "/home/kostya/Documents/project8_hw5/.venv/lib/python3.10/site-packages/django/core/checks/urls.py", line 14, in check_url_config
    return check_resolver(resolver)
  File "/home/kostya/Documents/project8_hw5/.venv/lib/python3.10/site-packages/django/core/checks/urls.py", line 24, in check_resolver
    return check_method()
  File "/home/kostya/Documents/project8_hw5/.venv/lib/python3.10/site-packages/django/urls/resolvers.py", line 519, in check
    for pattern in self.url_patterns:
  File "/home/kostya/Documents/project8_hw5/.venv/lib/python3.10/site-packages/django/utils/functional.py", line 47, in __get__
    res = instance.__dict__[self.name] = self.func(instance)
  File "/home/kostya/Documents/project8_hw5/.venv/lib/python3.10/site-packages/django/urls/resolvers.py", line 738, in url_patterns
    patterns = getattr(self.urlconf_module, "urlpatterns", self.urlconf_module)
  File "/home/kostya/Documents/project8_hw5/.venv/lib/python3.10/site-packages/django/utils/functional.py", line 47, in __get__
    res = instance.__dict__[self.name] = self.func(instance)
  File "/home/kostya/Documents/project8_hw5/.venv/lib/python3.10/site-packages/django/urls/resolvers.py", line 731, in urlconf_module
    return import_module(self.urlconf_name)
  File "/usr/lib/python3.10/importlib/__init__.py", line 126, in import_module
    return _bootstrap._gcd_import(name[level:], package, level)
  File "<frozen importlib._bootstrap>", line 1050, in _gcd_import
  File "<frozen importlib._bootstrap>", line 1027, in _find_and_load
  File "<frozen importlib._bootstrap>", line 1006, in _find_and_load_unlocked
  File "<frozen importlib._bootstrap>", line 688, in _load_unlocked
  File "<frozen importlib._bootstrap_external>", line 883, in exec_module
  File "<frozen importlib._bootstrap>", line 241, in _call_with_frames_removed
  File "/home/kostya/Documents/project8_hw5/askme_pupkin/urls.py", line 25, in <module>
    path('', include('app.urls'), name='index'),
  File "/home/kostya/Documents/project8_hw5/.venv/lib/python3.10/site-packages/django/urls/conf.py", line 39, in include
    urlconf_module = import_module(urlconf_module)
  File "/usr/lib/python3.10/importlib/__init__.py", line 126, in import_module
    return _bootstrap._gcd_import(name[level:], package, level)
  File "<frozen importlib._bootstrap>", line 1050, in _gcd_import
  File "<frozen importlib._bootstrap>", line 1027, in _find_and_load
  File "<frozen importlib._bootstrap>", line 1006, in _find_and_load_unlocked
  File "<frozen importlib._bootstrap>", line 688, in _load_unlocked
  File "<frozen importlib._bootstrap_external>", line 883, in exec_module
  File "<frozen importlib._bootstrap>", line 241, in _call_with_frames_removed
  File "/home/kostya/Documents/project8_hw5/app/urls.py", line 11, in <module>
    path('settings/', views.settings, name='settings'),
  File "/home/kostya/Documents/project8_hw5/.venv/lib/python3.10/site-packages/django/urls/conf.py", line 90, in _path
    raise TypeError(
TypeError: view must be a callable or a list/tuple in the case of include().
Traceback (most recent call last):
  File "/home/kostya/Documents/project8_hw5/manage.py", line 22, in <module>
    main()
  File "/home/kostya/Documents/project8_hw5/manage.py", line 18, in main
    execute_from_command_line(sys.argv)
  File "/home/kostya/Documents/project8_hw5/.venv/lib/python3.10/site-packages/django/core/management/__init__.py", line 442, in execute_from_command_line
    utility.execute()
  File "/home/kostya/Documents/project8_hw5/.venv/lib/python3.10/site-packages/django/core/management/__init__.py", line 436, in execute
    self.fetch_command(subcommand).run_from_argv(self.argv)
  File "/home/kostya/Documents/project8_hw5/.venv/lib/python3.10/site-packages/django/core/management/base.py", line 413, in run_from_argv
    self.execute(*args, **cmd_options)
  File "/home/kostya/Documents/project8_hw5/.venv/lib/python3.10/site-packages/django/core/management/base.py", line 454, in execute
    self.check()
  File "/home/kostya/Documents/project8_hw5/.venv/lib/python3.10/site-packages/django/core/management/base.py", line 486, in check
    all_issues = checks.run_checks(
  File "/home/kostya/Documents/project8_hw5/.venv/lib/python3.10/site-packages/django/core/checks/registry.py", line 88, in run_checks
    new_errors = check(app_configs=app_configs, databases=databases)
  File "/home/kostya/Documents/project8_hw5/.venv/lib/python3.10/site-packages/django/core/checks/urls.py", line 14, in check_url_config
    return check_resolver(resolver)
  File "/home/kostya/Documents/project8_hw5/.venv/lib/python3.10/site-packages/django/core/checks/urls.py", line 24, in check_resolver
    return check_method()
  File "/home/kostya/Documents/project8_hw5/.venv/lib/python3.10/site-packages/django/urls/resolvers.py", line 519, in check
    for pattern in self.url_patterns:
  File "/home/kostya/Documents/project8_hw5/.venv/lib/python3.10/site-packages/django/utils/functional.py", line 47, in __get__
    res = instance.__dict__[self.name] = self.func(instance)
  File "/home/kostya/Documents/project8_hw5/.venv/lib/python3.10/site-packages/django/urls/resolvers.py", line 738, in url_patterns
    patterns = getattr(self.urlconf_module, "urlpatterns", self.urlconf_module)
  File "/home/kostya/Documents/project8_hw5/.venv/lib/python3.10/site-packages/django/utils/functional.py", line 47, in __get__
    res = instance.__dict__[self.name] = self.func(instance)
  File "/home/kostya/Documents/project8_hw5/.venv/lib/python3.10/site-packages/django/urls/resolvers.py", line 731, in urlconf_module
    return import_module(self.urlconf_name)
  File "/usr/lib/python3.10/importlib/__init__.py", line 126, in import_module
    return _bootstrap._gcd_import(name[level:], package, level)
  File "<frozen importlib._bootstrap>", line 1050, in _gcd_import
  File "<frozen importlib._bootstrap>", line 1027, in _find_and_load
  File "<frozen importlib._bootstrap>", line 1006, in _find_and_load_unlocked
  File "<frozen importlib._bootstrap>", line 688, in _load_unlocked
  File "<frozen importlib._bootstrap_external>", line 883, in exec_module
  File "<frozen importlib._bootstrap>", line 241, in _call_with_frames_removed
  File "/home/kostya/Documents/project8_hw5/askme_pupkin/urls.py", line 25, in <module>
    path('', include('app.urls'), name='index'),
  File "/home/kostya/Documents/project8_hw5/.venv/lib/python3.10/site-packages/django/urls/conf.py", line 39, in include
    urlconf_module = import_module(urlconf_module)
  File "/usr/lib/python3.10/importlib/__init__.py", line 126, in import_module
    return _bootstrap._gcd_import(name[level:], package, level)
  File "<frozen importlib._bootstrap>", line 1050, in _gcd_import
  File "<frozen importlib._bootstrap>", line 1027, in _find_and_load
  File "<frozen importlib._bootstrap>", line 1006, in _find_and_load_unlocked
  File "<frozen importlib._bootstrap>", line 688, in _load_unlocked
  File "<frozen importlib._bootstrap_external>", line 883, in exec_module
  File "<frozen importlib._bootstrap>", line 241, in _call_with_frames_removed
  File "/home/kostya/Documents/project8_hw5/app/urls.py", line 11, in <module>
    path('settings/', views.settings, name='settings'),
  File "/home/kostya/Documents/project8_hw5/.venv/lib/python3.10/site-packages/django/urls/conf.py", line 90, in _path
    raise TypeError(
TypeError: view must be a callable or a list/tuple in the case of include().
Traceback (most recent call last):
  File "/home/kostya/Documents/project8_hw5/manage.py", line 22, in <module>
    main()
  File "/home/kostya/Documents/project8_hw5/manage.py", line 18, in main
    execute_from_command_line(sys.argv)
  File "/home/kostya/Documents/project8_hw5/.venv/lib/python3.10/site-packages/django/core/management/__init__.py", line 442, in execute_from_command_line
    utility.execute()
  File "/home/kostya/Documents/project8_hw5/.venv/lib/python3.10/site-packages/django/core/management/__init__.py", line 436, in execute
    self.fetch_command(subcommand).run_from_argv(self.argv)
  File "/home/kostya/Documents/project8_hw5/.venv/lib/python3.10/site-packages/django/core/management/base.py", line 413, in run_from_argv
    self.execute(*args, **cmd_options)
  File "/home/kostya/Documents/project8_hw5/.venv/lib/python3.10/site-packages/django/core/management/base.py", line 454, in execute
    self.check()
  File "/home/kostya/Documents/project8_hw5/.venv/lib/python3.10/site-packages/django/core/management/base.py", line 486, in check
    all_issues = checks.run_checks(
  File "/home/kostya/Documents/project8_hw5/.venv/lib/python3.10/site-packages/django/core/checks/registry.py", line 88, in run_checks
    new_errors = check(app_configs=app_configs, databases=databases)
  File "/home/kostya/Documents/project8_hw5/.venv/lib/python3.10/site-packages/django/core/checks/urls.py", line 14, in check_url_config
    return check_resolver(resolver)
  File "/home/kostya/Documents/project8_hw5/.venv/lib/python3.10/site-packages/django/core/checks/urls.py", line 24, in check_resolver
    return check_method()
  File "/home/kostya/Documents/project8_hw5/.venv/lib/python3.10/site-packages/django/urls/resolvers.py", line 519, in check
    for pattern in self.url_patterns:
  File "/home/kostya/Documents/project8_hw5/.venv/lib/python3.10/site-packages/django/utils/functional.py", line 47, in __get__
    res = instance.__dict__[self.name] = self.func(instance)
  File "/home/kostya/Documents/project8_hw5/.venv/lib/python3.10/site-packages/django/urls/resolvers.py", line 738, in url_patterns
    patterns = getattr(self.urlconf_module, "urlpatterns", self.urlconf_module)
  File "/home/kostya/Documents/project8_hw5/.venv/lib/python3.10/site-packages/django/utils/functional.py", line 47, in __get__
    res = instance.__dict__[self.name] = self.func(instance)
  File "/home/kostya/Documents/project8_hw5/.venv/lib/python3.10/site-packages/django/urls/resolvers.py", line 731, in urlconf_module
    return import_module(self.urlconf_name)
  File "/usr/lib/python3.10/importlib/__init__.py", line 126, in import_module
    return _bootstrap._gcd_import(name[level:], package, level)
  File "<frozen importlib._bootstrap>", line 1050, in _gcd_import
  File "<frozen importlib._bootstrap>", line 1027, in _find_and_load
  File "<frozen importlib._bootstrap>", line 1006, in _find_and_load_unlocked
  File "<frozen importlib._bootstrap>", line 688, in _load_unlocked
  File "<frozen importlib._bootstrap_external>", line 883, in exec_module
  File "<frozen importlib._bootstrap>", line 241, in _call_with_frames_removed
  File "/home/kostya/Documents/project8_hw5/askme_pupkin/urls.py", line 25, in <module>
    path('', include('app.urls'), name='index'),
  File "/home/kostya/Documents/project8_hw5/.venv/lib/python3.10/site-packages/django/urls/conf.py", line 39, in include
    urlconf_module = import_module(urlconf_module)
  File "/usr/lib/python3.10/importlib/__init__.py", line 126, in import_module
    return _bootstrap._gcd_import(name[level:], package, level)
  File "<frozen importlib._bootstrap>", line 1050, in _gcd_import
  File "<frozen importlib._bootstrap>", line 1027, in _find_and_load
  File "<frozen importlib._bootstrap>", line 1006, in _find_and_load_unlocked
  File "<frozen importlib._bootstrap>", line 688, in _load_unlocked
  File "<frozen importlib._bootstrap_external>", line 883, in exec_module
  File "<frozen importlib._bootstrap>", line 241, in _call_with_frames_removed
  File "/home/kostya/Documents/project8_hw5/app/urls.py", line 11, in <module>
    path('settings/', views.settings, name='settings'),
  File "/home/kostya/Documents/project8_hw5/.venv/lib/python3.10/site-packages/django/urls/conf.py", line 90, in _path
    raise TypeError(
TypeError: view must be a callable or a list/tuple in the case of include().
Traceback (most recent call last):
  File "/home/kostya/Documents/project8_hw5/manage.py", line 22, in <module>
    main()
  File "/home/kostya/Documents/project8_hw5/manage.py", line 18, in main
    execute_from_command_line(sys.argv)
  File "/home/kostya/Documents/project8_hw5/.venv/lib/python3.10/site-packages/django/core/management/__init__.py", line 442, in execute_from_command_line
    utility.execute()
  File "/home/kostya/Documents/project8_hw5/.venv/lib/python3.10/site-packages/django/core/management/__init__.py", line 436, in execute
    self.fetch_command(subcommand).run_from_argv(self.argv)
  File "/home/kostya/Documents/project8_hw5/.venv/lib/python3.10/site-packages/django/core/management/base.py", line 413, in run_from_argv
    self.execute(*args, **cmd_options)
  File "/home/kostya/Documents/project8_hw5/.venv/lib/python3.10/site-packages/django/core/management/base.py", line 454, in execute
    self.check()
  File "/home/kostya/Documents/project8_hw5/.venv/lib/python3.10/site-packages/django/core/management/base.py", line 486, in check
    all_issues = checks.run_checks(
  File "/home/kostya/Documents/project8_hw5/.venv/lib/python3.10/site-packages/django/core/checks/registry.py", line 88, in run_checks
    new_errors = check(app_configs=app_configs, databases=databases)
  File "/home/kostya/Documents/project8_hw5/.venv/lib/python3.10/site-packages/django/core/checks/urls.py", line 14, in check_url_config
    return check_resolver(resolver)
  File "/home/kostya/Documents/project8_hw5/.venv/lib/python3.10/site-packages/django/core/checks/urls.py", line 24, in check_resolver
    return check_method()
  File "/home/kostya/Documents/project8_hw5/.venv/lib/python3.10/site-packages/django/urls/resolvers.py", line 519, in check
    for pattern in self.url_patterns:
  File "/home/kostya/Documents/project8_hw5/.venv/lib/python3.10/site-packages/django/utils/functional.py", line 47, in __get__
    res = instance.__dict__[self.name] = self.func(instance)
  File "/home/kostya/Documents/project8_hw5/.venv/lib/python3.10/site-packages/django/urls/resolvers.py", line 738, in url_patterns
    patterns = getattr(self.urlconf_module, "urlpatterns", self.urlconf_module)
  File "/home/kostya/Documents/project8_hw5/.venv/lib/python3.10/site-packages/django/utils/functional.py", line 47, in __get__
    res = instance.__dict__[self.name] = self.func(instance)
  File "/home/kostya/Documents/project8_hw5/.venv/lib/python3.10/site-packages/django/urls/resolvers.py", line 731, in urlconf_module
    return import_module(self.urlconf_name)
  File "/usr/lib/python3.10/importlib/__init__.py", line 126, in import_module
    return _bootstrap._gcd_import(name[level:], package, level)
  File "<frozen importlib._bootstrap>", line 1050, in _gcd_import
  File "<frozen importlib._bootstrap>", line 1027, in _find_and_load
  File "<frozen importlib._bootstrap>", line 1006, in _find_and_load_unlocked
  File "<frozen importlib._bootstrap>", line 688, in _load_unlocked
  File "<frozen importlib._bootstrap_external>", line 883, in exec_module
  File "<frozen importlib._bootstrap>", line 241, in _call_with_frames_removed
  File "/home/kostya/Documents/project8_hw5/askme_pupkin/urls.py", line 25, in <module>
    path('', include('app.urls'), name='index'),
  File "/home/kostya/Documents/project8_hw5/.venv/lib/python3.10/site-packages/django/urls/conf.py", line 39, in include
    urlconf_module = import_module(urlconf_module)
  File "/usr/lib/python3.10/importlib/__init__.py", line 126, in import_module
    return _bootstrap._gcd_import(name[level:], package, level)
  File "<frozen importlib._bootstrap>", line 1050, in _gcd_import
  File "<frozen importlib._bootstrap>", line 1027, in _find_and_load
  File "<frozen importlib._bootstrap>", line 1006, in _find_and_load_unlocked
  File "<frozen importlib._bootstrap>", line 688, in _load_unlocked
  File "<frozen importlib._bootstrap_external>", line 883, in exec_module
  File "<frozen importlib._bootstrap>", line 241, in _call_with_frames_removed
  File "/home/kostya/Documents/project8_hw5/app/urls.py", line 11, in <module>
    path('settings/', views.settings, name='settings'),
  File "/home/kostya/Documents/project8_hw5/.venv/lib/python3.10/site-packages/django/urls/conf.py", line 90, in _path
    raise TypeError(
TypeError: view must be a callable or a list/tuple in the case of include().
Traceback (most recent call last):
  File "/home/kostya/Documents/project8_hw5/manage.py", line 22, in <module>
    main()
  File "/home/kostya/Documents/project8_hw5/manage.py", line 18, in main
    execute_from_command_line(sys.argv)
  File "/home/kostya/Documents/project8_hw5/.venv/lib/python3.10/site-packages/django/core/management/__init__.py", line 442, in execute_from_command_line
    utility.execute()
  File "/home/kostya/Documents/project8_hw5/.venv/lib/python3.10/site-packages/django/core/management/__init__.py", line 436, in execute
    self.fetch_command(subcommand).run_from_argv(self.argv)
  File "/home/kostya/Documents/project8_hw5/.venv/lib/python3.10/site-packages/django/core/management/base.py", line 413, in run_from_argv
    self.execute(*args, **cmd_options)
  File "/home/kostya/Documents/project8_hw5/.venv/lib/python3.10/site-packages/django/core/management/base.py", line 454, in execute
    self.check()
  File "/home/kostya/Documents/project8_hw5/.venv/lib/python3.10/site-packages/django/core/management/base.py", line 486, in check
    all_issues = checks.run_checks(
  File "/home/kostya/Documents/project8_hw5/.venv/lib/python3.10/site-packages/django/core/checks/registry.py", line 88, in run_checks
    new_errors = check(app_configs=app_configs, databases=databases)
  File "/home/kostya/Documents/project8_hw5/.venv/lib/python3.10/site-packages/django/core/checks/urls.py", line 14, in check_url_config
    return check_resolver(resolver)
  File "/home/kostya/Documents/project8_hw5/.venv/lib/python3.10/site-packages/django/core/checks/urls.py", line 24, in check_resolver
    return check_method()
  File "/home/kostya/Documents/project8_hw5/.venv/lib/python3.10/site-packages/django/urls/resolvers.py", line 519, in check
    for pattern in self.url_patterns:
  File "/home/kostya/Documents/project8_hw5/.venv/lib/python3.10/site-packages/django/utils/functional.py", line 47, in __get__
    res = instance.__dict__[self.name] = self.func(instance)
  File "/home/kostya/Documents/project8_hw5/.venv/lib/python3.10/site-packages/django/urls/resolvers.py", line 738, in url_patterns
    patterns = getattr(self.urlconf_module, "urlpatterns", self.urlconf_module)
  File "/home/kostya/Documents/project8_hw5/.venv/lib/python3.10/site-packages/django/utils/functional.py", line 47, in __get__
    res = instance.__dict__[self.name] = self.func(instance)
  File "/home/kostya/Documents/project8_hw5/.venv/lib/python3.10/site-packages/django/urls/resolvers.py", line 731, in urlconf_module
    return import_module(self.urlconf_name)
  File "/usr/lib/python3.10/importlib/__init__.py", line 126, in import_module
    return _bootstrap._gcd_import(name[level:], package, level)
  File "<frozen importlib._bootstrap>", line 1050, in _gcd_import
  File "<frozen importlib._bootstrap>", line 1027, in _find_and_load
  File "<frozen importlib._bootstrap>", line 1006, in _find_and_load_unlocked
  File "<frozen importlib._bootstrap>", line 688, in _load_unlocked
  File "<frozen importlib._bootstrap_external>", line 883, in exec_module
  File "<frozen importlib._bootstrap>", line 241, in _call_with_frames_removed
  File "/home/kostya/Documents/project8_hw5/askme_pupkin/urls.py", line 25, in <module>
    path('', include('app.urls'), name='index'),
  File "/home/kostya/Documents/project8_hw5/.venv/lib/python3.10/site-packages/django/urls/conf.py", line 39, in include
    urlconf_module = import_module(urlconf_module)
  File "/usr/lib/python3.10/importlib/__init__.py", line 126, in import_module
    return _bootstrap._gcd_import(name[level:], package, level)
  File "<frozen importlib._bootstrap>", line 1050, in _gcd_import
  File "<frozen importlib._bootstrap>", line 1027, in _find_and_load
  File "<frozen importlib._bootstrap>", line 1006, in _find_and_load_unlocked
  File "<frozen importlib._bootstrap>", line 688, in _load_unlocked
  File "<frozen importlib._bootstrap_external>", line 883, in exec_module
  File "<frozen importlib._bootstrap>", line 241, in _call_with_frames_removed
  File "/home/kostya/Documents/project8_hw5/app/urls.py", line 11, in <module>
    path('settings/', views.settings, name='settings'),
  File "/home/kostya/Documents/project8_hw5/.venv/lib/python3.10/site-packages/django/urls/conf.py", line 90, in _path
    raise TypeError(
TypeError: view must be a callable or a list/tuple in the case of include().
